<mujoco model="planar hopper">
  <include file="./common/skybox.xml"/>
  <include file="./common/visual.xml"/>
  <include file="./common/materials.xml"/>

  <statistic extent="2" center="0 0 .5"/>

  <default>
    <default class="hopper">
      <joint type="hinge" axis="0 1 0" limited="true" damping=".05" armature=".2"/>
      <geom type="capsule" material="self"/>
      <site type="sphere" size="0.05" group="3"/>
    </default>
    <default class="free">
      <joint limited="false" damping="0" armature="0" stiffness="0"/>
    </default>
    <motor ctrlrange="-1 1" ctrllimited="true"/>
  </default>

  <option timestep="0.005"/>

  <asset>
    <hfield name="terrain" ncol="2000" nrow="5" size="100 0.5 0.6 1"/>
  </asset>

  <worldbody>
    <geom name="terrain" conaffinity="1"  type="hfield" hfield="terrain" rgba=".8 .1 .4 1" pos="0 0 -.5"/>
    <camera name="cam0" pos="0 -2.5 0.8" euler="90 0 0" mode="trackcom"/>
    <camera name="back" pos="-2 -.2 1.2" xyaxes="0.2 -1 0 .5 0 2" mode="trackcom"/>
    <body name="torso" pos="0 0 1" childclass="hopper">
      <light name="top" pos="0 0 2" mode="trackcom"/>
      <joint name="rootx" type="slide" axis="1 0 0" class="free"/>
      <joint name="rootz" type="slide" axis="0 0 1" class="free"/>
      <joint name="rooty" type="hinge" axis="0 1 0" class="free"/>
      <geom name="torso" fromto="0 0 -.05 0 0 .2" size="0.0653"/>