<mujoco model="planar walker">
  <include file="./common/visual.xml"/>
  <include file="./common/skybox.xml"/>
  <include file="./common/materials.xml"/>

  <option timestep="0.0025"/>

  <statistic extent="2" center="0 0 1"/>

  <default>
    <joint damping=".1" armature="0.01" limited="true" solimplimit="0 .99 .01"/>
    <geom contype="1" conaffinity="0" friction=".7 .1 .1"/>
    <motor ctrlrange="-1 1" ctrllimited="true"/>
    <site size="0.01"/>
    <default class="walker">
      <geom material="self" type="capsule"/>
      <joint axis="0 -1 0"/>
    </default>
  </default>

  <asset>
    <hfield name="terrain" ncol="2000" nrow="5" size="100 0.5 0.9 1"/>
  </asset>

  <worldbody>
    <geom name="terrain" conaffinity="1"  type="hfield" hfield="terrain" rgba=".8 .1 .4 1" pos="0 0 -.5"/>
    <body name="torso" pos="0 0 1.3" childclass="walker">
      <light name="light" pos="0 0 2" mode="trackcom"/>
      <camera name="side" pos="0 -3.0 -0.2" euler="85 0 0" mode="trackcom"/>
      <camera name="back" pos="-4 0 .5" xyaxes="0 -1 0 1 0 3" mode="trackcom"/>
      <joint name="rootz" axis="0 0 1" type="slide" limited="false" armature="0" damping="0"/>
      <joint name="rootx" axis="1 0 0" type="slide" limited="false" armature="0" damping="0"/>
      <joint name="rooty" axis="0 1 0" type="hinge" limited="false" armature="0" damping